{
 "cells": [
  {
   "cell_type": "code",
   "execution_count": 8,
   "id": "atomic-constant",
   "metadata": {},
   "outputs": [
    {
     "ename": "ImportError",
     "evalue": "cannot import name 'get_data' from 'Insurance_claiming_forecasting' (/Users/valeriarevolledo/.pyenv/versions/3.8.6/envs/lewagon/lib/python3.8/site-packages/Insurance_claiming_forecasting/__init__.py)",
     "output_type": "error",
     "traceback": [
      "\u001b[0;31m---------------------------------------------------------------------------\u001b[0m",
      "\u001b[0;31mImportError\u001b[0m                               Traceback (most recent call last)",
      "\u001b[0;32m<ipython-input-8-3714ac257b50>\u001b[0m in \u001b[0;36m<module>\u001b[0;34m\u001b[0m\n\u001b[0;32m----> 1\u001b[0;31m \u001b[0;32mfrom\u001b[0m \u001b[0mInsurance_claiming_forecasting\u001b[0m \u001b[0;32mimport\u001b[0m \u001b[0mget_data\u001b[0m\u001b[0;34m\u001b[0m\u001b[0;34m\u001b[0m\u001b[0m\n\u001b[0m",
      "\u001b[0;31mImportError\u001b[0m: cannot import name 'get_data' from 'Insurance_claiming_forecasting' (/Users/valeriarevolledo/.pyenv/versions/3.8.6/envs/lewagon/lib/python3.8/site-packages/Insurance_claiming_forecasting/__init__.py)"
     ]
    }
   ],
   "source": [
    "from Insurance_claiming_forecasting import get_data"
   ]
  }
 ],
 "metadata": {
  "kernelspec": {
   "display_name": "Python 3",
   "language": "python",
   "name": "python3"
  },
  "language_info": {
   "codemirror_mode": {
    "name": "ipython",
    "version": 3
   },
   "file_extension": ".py",
   "mimetype": "text/x-python",
   "name": "python",
   "nbconvert_exporter": "python",
   "pygments_lexer": "ipython3",
   "version": "3.8.6"
  }
 },
 "nbformat": 4,
 "nbformat_minor": 5
}
